<?xml version="1.0" encoding="utf-8" ?>
<!-- Copied from
SO-ARM100/URDF/SO_5DOF_ARM100_8j_URDF.SLDASM/urdf/SO_5DOF_ARM100_8j_URDF.SLDASM.urdf with minimal
changes:
- package://SO_5DOF_ARM100_8j_URDF.SLDASM -> package://so_arm100_description
- Moving Jaw.STL -> Moving_Jaw.STL
- Link names:
  - Base -> base
  - Rotation_Pitch -> shoulder_link
  - Upper_Arm -> upper_arm_link
  - Lower_Arm -> forearm_link
  - Wrist_Pitch_Roll -> wrist_1_link
  - Fixed_Jaw -> wrist_2_link
  - Moving Jaw -> jaw_link
- Joint names:
  - Rotation -> shoulder_pan_joint
  - Pitch -> shoulder_lift_joint
  - Elbow -> elbow_joint
  - Wrist_Pitch -> wrist_pitch_joint
  - Wrist_Roll -> wrist_roll_joint
  - Jaw -> jaw_joint
-->
<robot xmlns:xacro="http://ros.org/wiki/xacro">
  <xacro:macro name="so_arm100" params="prefix">
    <link name="${prefix}base">
      <inertial>
        <origin
          xyz="-2.45960666746703E-07 0.0311418169687909 0.0175746661003382"
          rpy="0 0 0"
        />
        <mass value="0.193184127927598" />
        <inertia
          ixx="0.000137030709467877"
          ixy="2.10136126944992E-08"
          ixz="4.24087422551286E-09"
          iyy="0.000169089551209259"
          iyz="2.26514711036514E-05"
          izz="0.000145097720857224"
        />
      </inertial>
      <visual>
        <origin xyz="0 0 0" rpy="0 0 0" />
        <geometry>
          <mesh filename="package://so_arm100_description/SO-ARM101-Assets/base_motor_holder_so101_v1.stl" />
        </geometry>
        <material name="">
          <color
            rgba="0.792156862745098 0.819607843137255 0.933333333333333 1"
          />
        </material>
      </visual>
      <collision>
        <origin xyz="0 0 0" rpy="0 0 0" />
        <geometry>
          <mesh filename="package://so_arm100_description/SO-ARM101-Assets/base_motor_holder_so101_v1.stl" />
        </geometry>
      </collision>
    </link>
    <link name="${prefix}shoulder_link">
      <inertial>
        <origin
          xyz="-9.07886224712597E-05 0.0590971820568318 0.031089016892169"
          rpy="0 0 0"
        />
        <mass value="0.119226314127197" />
        <inertia
          ixx="5.90408775624429E-05"
          ixy="4.90800532852998E-07"
          ixz="-5.90451772654387E-08"
          iyy="3.21498601038881E-05"
          iyz="-4.58026206663885E-06"
          izz="5.86058514263952E-05"
        />
      </inertial>
      <visual>
        <origin xyz="-0.0303992 0.000422241 -0.0417" rpy="1.5708 1.5708 0" />
        <geometry>
          <mesh filename="package://so_arm100_description/SO-ARM101-Assets/sts3215_03a_v1.stl" />
        </geometry>
        <material name="sts3215"/>
      </visual>
      <visual>
        <origin xyz="-0.0675992 -0.000177759 0.0158499" rpy="1.5708 -1.5708 0" />
        <geometry>
          <mesh filename="package://so_arm100_description/SO-ARM101-Assets/motor_holder_so101_base_v1.stl" />
        </geometry>
        <material name="3d_printed"/>
      </visual>
      <visual>
        <origin xyz="0 0 0" rpy="0 0 0" />
        <geometry>
          <mesh filename="package://so_arm100_description/SO-ARM101-Assets/rotation_pitch_so101_v1.stl" />
        </geometry>
      </visual>
      <collision>
        <origin xyz="-0.0303992 0.000422241 -0.0417" rpy="1.5708 1.5708 0" />
        <geometry>
          <mesh filename="package://so_arm100_description/SO-ARM101-Assets/sts3215_03a_v1.stl" />
        </geometry>
      </collision>
    </link>
    <joint name="${prefix}shoulder_pan_joint" type="revolute">
      <origin xyz="0.0388353 0 0.0459" rpy="0 0 0" />
      <parent link="${prefix}base" />
      <child link="${prefix}shoulder_link" />
      <axis xyz="0 0 1" />
      <limit effort="10" velocity="10" lower="-1.91986" upper="1.91986" />
    </joint>
    <link name="${prefix}upper_arm_link">
      <inertial>
        <origin
          xyz="-1.7205170190925E-05 0.0701802156327694 0.00310545118155671"
          rpy="0 0 0"
        />
        <mass value="0.162409284599177" />
        <inertia
          ixx="0.000167153146617081"
          ixy="1.03902689187701E-06"
          ixz="-1.20161820645189E-08"
          iyy="7.01946992214245E-05"
          iyz="2.11884806298698E-06"
          izz="0.000213280241160769"
        />
      </inertial>
      <visual>
        <origin xyz="0 0 0" rpy="0 0 0" />
        <geometry>
          <mesh filename="package://so_arm100_description/SO-ARM101-Assets/sts3215_03a_v1.stl" />
        </geometry>
        <material name="sts3215"/>
      </visual>
      <visual>
        <origin xyz="0 0 0" rpy="0 0 0" />
        <geometry>
          <mesh filename="package://so_arm100_description/SO-ARM101-Assets/upper_arm_so101_v1.stl" />
        </geometry>
      </visual>
      <collision>
        <origin xyz="0 0 0" rpy="0 0 0" />
        <geometry>
          <mesh filename="package://so_arm100_description/SO-ARM101-Assets/upper_arm_so101_v1.stl" />
        </geometry>
      </collision>
    </link>
    <joint name="${prefix}shoulder_lift_joint" type="revolute">
      <origin xyz="0 0 0.0624" rpy="3.14159 0 0" />
      <parent link="${prefix}shoulder_link" />
      <child link="${prefix}upper_arm_link" />
      <axis xyz="0 0 1" />
      <limit effort="10" velocity="10" lower="-1.74533" upper="1.74533" />
    </joint>
    <link name="${prefix}forearm_link">
      <inertial>
        <origin
          xyz="-0.00339603710186651 0.00137796353960074 0.0768006751156044"
          rpy="0 0 0"
        />
        <mass value="0.147967774582291" />
        <inertia
          ixx="0.000105333995841409"
          ixy="1.73059237226499E-07"
          ixz="-1.1720305455211E-05"
          iyy="0.000138766654485212"
          iyz="1.77429964684103E-06"
          izz="5.08741652515214E-05"
        />
      </inertial>
      <visual>
        <origin xyz="0 0 0" rpy="0 0 0" />
        <geometry>
          <mesh filename="package://so_arm100_description/SO-ARM101-Assets/under_arm_so101_v1.stl" />
        </geometry>
        <material name="3d_printed"/>
      </visual>
      <visual>
        <origin xyz="0 0 0" rpy="0 0 0" />
        <geometry>
          <mesh filename="package://so_arm100_description/SO-ARM101-Assets/motor_holder_so101_wrist_v1.stl" />
        </geometry>
      </visual>
      <visual>
        <origin xyz="0 0 0" rpy="0 0 0" />
        <geometry>
          <mesh filename="package://so_arm100_description/SO-ARM101-Assets/sts3215_03a_v1.stl" />
        </geometry>
        <material name="sts3215"/>
      </visual>
      <collision>
        <origin xyz="0 0 0" rpy="0 0 0" />
        <geometry>
          <mesh filename="package://so_arm100_description/SO-ARM101-Assets/under_arm_so101_v1.stl" />
        </geometry>
      </collision>
    </link>
    <joint name="${prefix}elbow_joint" type="revolute">
      <origin xyz="-0.0303992 -0.0182778 -0.0542" rpy="-1.5708 -1.5708 0" />
      <parent link="${prefix}upper_arm_link" />
      <child link="${prefix}forearm_link" />
      <axis xyz="0 0 1" />
      <limit effort="10" velocity="10" lower="-1.69" upper="1.69" />
    </joint>
    <link name="${prefix}wrist_1_link">
      <inertial>
        <origin
          xyz="-0.00852653127372418 -0.0352278997897927 -2.34622481569413E-05"
          rpy="0 0 0"
        />
        <mass value="0.066132067097723" />
        <inertia
          ixx="1.95717492443445E-05"
          ixy="-6.62714374412293E-07"
          ixz="5.20089016442066E-09"
          iyy="2.38028417569933E-05"
          iyz="4.09549055863776E-08"
          izz="3.4540143384536E-05"
        />
      </inertial>
      <visual>
        <origin xyz="0 0 0" rpy="0 0 0" />
        <geometry>
          <mesh filename="package://so_arm100_description/SO-ARM101-Assets/sts3215_03a_no_horn_v1.stl" />
        </geometry>
        <material name="sts3215"/>
      </visual>
      <visual>
        <origin xyz="0 0 0" rpy="0 0 0" />
        <geometry>
          <mesh filename="package://so_arm100_description/SO-ARM101-Assets/wrist_roll_pitch_so101_v2.stl" />
        </geometry>
      </visual>
      <collision>
        <origin xyz="0 0 0" rpy="0 0 0" />
        <geometry>
          <mesh filename="package://so_arm100_description/SO-ARM101-Assets/sts3215_03a_no_horn_v1.stl" />
        </geometry>
      </collision>
    </link>
    <joint name="${prefix}wrist_pitch_joint" type="revolute">
      <origin xyz="-0.1224 0.0052 0.0187" rpy="-3.14159 0 -3.14159" />
      <parent link="${prefix}forearm_link" />
      <child link="${prefix}wrist_1_link" />
      <axis xyz="0 0 1" />
      <limit effort="10" velocity="10" lower="-1.65806" upper="1.65806" />
    </joint>
    <link name="${prefix}wrist_2_link">
      <inertial>
        <origin
          xyz="0.00552376906426563 -0.0280167153359021 0.000483582592841092"
          rpy="0 0 0"
        />
        <mass value="0.0929859131176897" />
        <inertia
          ixx="4.3328249304211E-05"
          ixy="7.09654328670947E-06"
          ixz="5.99838530879484E-07"
          iyy="3.04451747368212E-05"
          iyz="-1.58743247545413E-07"
          izz="5.02460913506734E-05"
        />
      </inertial>
      <visual>
        <origin xyz="0 0 0" rpy="0 0 0" />
        <geometry>
          <mesh filename="package://so_arm100_description/SO-ARM101-Assets/sts3215_03a_v1.stl" />
        </geometry>
        <material name="sts3215"/>
      </visual>
      <visual>
        <origin xyz="0 0 0" rpy="0 0 0" />
        <geometry>
          <mesh filename="package://so_arm100_description/SO-ARM101-Assets/wrist_roll_follower_so101_v1.stl" />
        </geometry>
      </visual>
      <collision>
        <origin xyz="0 0 0" rpy="0 0 0" />
        <geometry>
          <mesh filename="package://so_arm100_description/SO-ARM101-Assets/sts3215_03a_v1.stl" />
        </geometry>
      </collision>
    </link>
    <joint name="${prefix}wrist_roll_joint" type="revolute">
      <origin xyz="5.55112e-17 -0.0611 0.0181" rpy="1.5708 0.0486795 3.14159" />
      <parent link="${prefix}wrist_1_link" />
      <child link="${prefix}wrist_2_link" />
      <axis xyz="0 0 1" />
      <limit effort="10" velocity="10" lower="-2.74385" upper="2.84121" />
    </joint>
    <link name="${prefix}jaw_link">
      <inertial>
        <origin
          xyz="-0.00161744605468241 -0.0303472584046471 0.000449645961853651"
          rpy="0 0 0"
        />
        <mass value="0.0202443794940372" />
        <inertia
          ixx="1.10911325081525E-05"
          ixy="-5.35076503033314E-07"
          ixz="-9.46105662101403E-09"
          iyy="3.03576451001973E-06"
          iyz="-1.71146075110632E-07"
          izz="8.9916083370498E-06"
        />
      </inertial>
      <visual>
        <origin xyz="0 0 0" rpy="0 0 0" />
        <geometry>
          <mesh filename="package://so_arm100_description/SO-ARM101-Assets/moving_jaw_so101_v1.stl" />
        </geometry>
        <material name="3d_printed"/>
      </visual>
      <collision>
        <origin xyz="0 0 0" rpy="0 0 0" />
        <geometry>
          <mesh filename="package://so_arm100_description/SO-ARM101-Assets/moving_jaw_so101_v1.stl" />
        </geometry>
      </collision>
    </link>
    <!-- Gripper frame (dummy link + fixed joint) -->
    <link name="${prefix}gripper_frame_link">
      <inertial>
        <origin xyz="0 0 0" rpy="0 0 0"/>
        <mass value="1e-9"/>
        <inertia ixx="0" ixy="0" ixz="0" iyy="0" iyz="0" izz="0"/>
      </inertial>
    </link>

    <joint name="${prefix}gripper_frame_joint" type="fixed">
      <origin xyz="-0.0079 -0.000218121 -0.0981274" rpy="0 3.14159 0"/>
      <parent link="${prefix}wrist_2_link"/>
      <child link="${prefix}gripper_frame_link"/>
      <axis xyz="0 0 0"/>
    </joint>

    <joint name="${prefix}jaw_joint" type="revolute">
      <origin xyz="0.0202 0.0188 -0.0234" rpy="1.5708 -5.24284e-08 -1.41553e-15"/>
      <parent link="${prefix}wrist_2_link" />
      <child link="${prefix}jaw_link" />
      <axis xyz="0 0 1" />
      <limit effort="10" velocity="10" lower="-0.174533" upper="1.74533" />
    </joint>
  </xacro:macro>
</robot>
